<mujoco model="orcabot">
  <compiler angle="radian" />
  <default>
    <default class="arm_joint">
      <joint damping="20.0" armature="0.5" />
      <position kp="2000.0" kv="100.0" ctrlrange="-3.14 3.14" forcerange="-200 200" />
    </default>
    <default class="hand_joint">
      <joint damping="0.5" armature="0.001" />
      <position kp="20.0" kv="1.0" ctrlrange="-2 2" forcerange="-5 5" />
    </default>
  </default>
  <asset>
    <mesh name="4dc06ed0_body_link0" content_type="model/stl" file="assets/4dc06ed0_body_link0.stl" scale="0.001 0.001 0.001" />
    <mesh name="793addde_body_link0_symp" content_type="model/stl" file="assets/793addde_body_link0_symp.stl" scale="0.001 0.001 0.001" />
    <mesh name="9ba3e77f_link0" content_type="model/stl" file="assets/9ba3e77f_link0.stl" scale="0.001 -0.001 0.001" />
    <mesh name="5da9d14d_link0_symp" content_type="model/stl" file="assets/5da9d14d_link0_symp.stl" scale="0.001 -0.001 0.001" />
    <mesh name="3ebfcf76_link1" content_type="model/stl" file="assets/3ebfcf76_link1.stl" scale="0.001 -0.001 0.001" />
    <mesh name="77e5ad00_link1_symp" content_type="model/stl" file="assets/77e5ad00_link1_symp.stl" scale="0.001 -0.001 0.001" />
    <mesh name="9c17496a_link2" content_type="model/stl" file="assets/9c17496a_link2.stl" scale="0.001 -0.001 0.001" />
    <mesh name="775eb093_link2_symp" content_type="model/stl" file="assets/775eb093_link2_symp.stl" scale="0.001 -0.001 0.001" />
    <mesh name="95d3aa89_link3" content_type="model/stl" file="assets/95d3aa89_link3.stl" scale="0.001 -0.001 0.001" />
    <mesh name="dee04699_link3_symp" content_type="model/stl" file="assets/dee04699_link3_symp.stl" scale="0.001 -0.001 0.001" />
    <mesh name="c8eeff55_link4" content_type="model/stl" file="assets/c8eeff55_link4.stl" scale="0.001 0.001 0.001" />
    <mesh name="c98343f3_link4_symp" content_type="model/stl" file="assets/c98343f3_link4_symp.stl" scale="0.001 0.001 0.001" />
    <mesh name="9ba3e77f_link01" content_type="model/stl" file="assets/9ba3e77f_link0.stl" scale="0.001 0.001 0.001" />
    <mesh name="5da9d14d_link0_symp1" content_type="model/stl" file="assets/5da9d14d_link0_symp.stl" scale="0.001 0.001 0.001" />
    <mesh name="3ebfcf76_link11" content_type="model/stl" file="assets/3ebfcf76_link1.stl" scale="0.001 0.001 0.001" />
    <mesh name="77e5ad00_link1_symp1" content_type="model/stl" file="assets/77e5ad00_link1_symp.stl" scale="0.001 0.001 0.001" />
    <mesh name="9c17496a_link21" content_type="model/stl" file="assets/9c17496a_link2.stl" scale="0.001 0.001 0.001" />
    <mesh name="775eb093_link2_symp1" content_type="model/stl" file="assets/775eb093_link2_symp.stl" scale="0.001 0.001 0.001" />
    <mesh name="95d3aa89_link31" content_type="model/stl" file="assets/95d3aa89_link3.stl" scale="0.001 0.001 0.001" />
    <mesh name="dee04699_link3_symp1" content_type="model/stl" file="assets/dee04699_link3_symp.stl" scale="0.001 0.001 0.001" />
    <mesh name="right_ForeArmStructure-Model" content_type="model/stl" file="assets/right_ForeArmStructure-Model.stl" scale="0.001 0.001 0.001" />
    <mesh name="right_TopTower-Model" content_type="model/stl" file="assets/right_TopTower-Model.stl" scale="0.001 0.001 0.001" />
    <mesh name="right_R-Carpals" content_type="model/stl" file="assets/right_R-Carpals.stl" scale="0.001 0.001 0.001" />
    <mesh name="right_P-AP" content_type="model/stl" file="assets/right_P-AP.stl" scale="0.001 0.001 0.001" />
    <mesh name="right_P-PP" content_type="model/stl" file="assets/right_P-PP.stl" scale="0.001 0.001 0.001" />
    <mesh name="right_P-FingerTipAssembly" content_type="model/stl" file="assets/right_P-FingerTipAssembly.stl" scale="0.001 0.001 0.001" />
    <mesh name="right_M-AP" content_type="model/stl" file="assets/right_M-AP.stl" scale="0.001 0.001 0.001" />
    <mesh name="right_M-PP" content_type="model/stl" file="assets/right_M-PP.stl" scale="0.001 0.001 0.001" />
    <mesh name="right_M-FingerTipAssembly" content_type="model/stl" file="assets/right_M-FingerTipAssembly.stl" scale="0.001 0.001 0.001" />
    <mesh name="right_I-AP-R" content_type="model/stl" file="assets/right_I-AP-R.stl" scale="0.001 0.001 0.001" />
    <mesh name="right_I-PP" content_type="model/stl" file="assets/right_I-PP.stl" scale="0.001 0.001 0.001" />
    <mesh name="right_I-FingerTipAssembly" content_type="model/stl" file="assets/right_I-FingerTipAssembly.stl" scale="0.001 0.001 0.001" />
    <mesh name="right_T-TP-R" content_type="model/stl" file="assets/right_T-TP-R.stl" scale="0.001 0.001 0.001" />
    <mesh name="right_R-T-AP" content_type="model/stl" file="assets/right_R-T-AP.stl" scale="0.001 0.001 0.001" />
    <mesh name="right_T-PP" content_type="model/stl" file="assets/right_T-PP.stl" scale="0.001 0.001 0.001" />
    <mesh name="right_T-DP" content_type="model/stl" file="assets/right_T-DP.stl" scale="0.001 0.001 0.001" />
    <mesh name="left_ForeArmStructure-Model" content_type="model/stl" file="assets/left_ForeArmStructure-Model.stl" scale="0.001 0.001 0.001" />
    <mesh name="left_TopTower-Model" content_type="model/stl" file="assets/left_TopTower-Model.stl" scale="0.001 0.001 0.001" />
    <mesh name="left_L-Carpals" content_type="model/stl" file="assets/left_L-Carpals.stl" scale="0.001 0.001 0.001" />
    <mesh name="left_P-AP" content_type="model/stl" file="assets/left_P-AP.stl" scale="0.001 0.001 0.001" />
    <mesh name="left_P-PP" content_type="model/stl" file="assets/left_P-PP.stl" scale="0.001 0.001 0.001" />
    <mesh name="left_P-FingerTipAssembly" content_type="model/stl" file="assets/left_P-FingerTipAssembly.stl" scale="0.001 0.001 0.001" />
    <mesh name="left_M-AP" content_type="model/stl" file="assets/left_M-AP.stl" scale="0.001 0.001 0.001" />
    <mesh name="left_M-PP" content_type="model/stl" file="assets/left_M-PP.stl" scale="0.001 0.001 0.001" />
    <mesh name="left_M-FingerTipAssembly" content_type="model/stl" file="assets/left_M-FingerTipAssembly.stl" scale="0.001 0.001 0.001" />
    <mesh name="left_I-AP-L" content_type="model/stl" file="assets/left_I-AP-L.stl" scale="0.001 0.001 0.001" />
    <mesh name="left_I-PP" content_type="model/stl" file="assets/left_I-PP.stl" scale="0.001 0.001 0.001" />
    <mesh name="left_I-FingerTipAssembly" content_type="model/stl" file="assets/left_I-FingerTipAssembly.stl" scale="0.001 0.001 0.001" />
    <mesh name="left_T-TP-L" content_type="model/stl" file="assets/left_T-TP-L.stl" scale="0.001 0.001 0.001" />
    <mesh name="left_L-T-AP" content_type="model/stl" file="assets/left_L-T-AP.stl" scale="0.001 0.001 0.001" />
    <mesh name="left_T-PP" content_type="model/stl" file="assets/left_T-PP.stl" scale="0.001 0.001 0.001" />
    <mesh name="left_T-DP" content_type="model/stl" file="assets/left_T-DP.stl" scale="0.001 0.001 0.001" />
  </asset>
  <worldbody>
    <body name="openarm_body_link0">
      <inertial pos="0 0 0" mass="13.89" diaginertia="1.653 1.653 0.051" />
      <geom name="openarm_body_link0_visual" type="mesh" contype="0" conaffinity="0" group="1" density="0" mesh="4dc06ed0_body_link0" />
      <geom name="openarm_body_link0_collision" type="mesh" mesh="793addde_body_link0_symp" />
      <body name="openarm_left_link0" pos="0 0.031 0.698" quat="0.707105 -0.707108 0 0">
        <inertial pos="-0.000948336 -0.000158021 0.0307686" quat="0.479051 0.472241 -0.533622 0.512587" mass="1.14323" diaginertia="0.00147324 0.00112498 0.000961783" />
        <geom name="openarm_left_link0_visual" type="mesh" contype="0" conaffinity="0" group="1" density="0" mesh="9ba3e77f_link0" />
        <geom name="openarm_left_link0_collision" type="mesh" mesh="5da9d14d_link0_symp" />
        <body name="openarm_left_link1" pos="0 0 0.0625">
          <inertial pos="0.00114677 -3.31999e-05 0.0539528" quat="0.999653 0.00178277 0.0262159 -0.0018256" mass="1.14167" diaginertia="0.00156853 0.001273 0.00101447" />
          <joint name="openarm_left_joint1" pos="0 0 0" axis="0 0 1" range="-3.49066 1.39626" actuatorfrcrange="-40 40" class="arm_joint" />
          <geom name="openarm_left_link1_visual" pos="0 0 -0.0625" type="mesh" contype="0" conaffinity="0" group="1" density="0" mesh="3ebfcf76_link1" />
          <geom name="openarm_left_link1_collision" pos="0 0 -0.0625" type="mesh" mesh="77e5ad00_link1_symp" />
          <body name="openarm_left_link2" pos="-0.0301 0 0.06" quat="0.707107 -0.707107 0 0">
            <inertial pos="0.00839629 2.01451e-08 0.0325665" quat="0.966167 0.00423301 0.257864 0.00305037" mass="0.277509" diaginertia="0.000421651 0.000376006 0.000169343" />
            <joint name="openarm_left_joint2" pos="0 0 0" axis="-1 0 0" range="-3.31613 0.174533" actuatorfrcrange="-40 40" class="arm_joint" />
            <geom name="openarm_left_link2_visual" pos="0.0301 0 -0.1225" type="mesh" contype="0" conaffinity="0" group="1" density="0" mesh="9c17496a_link2" />
            <geom name="openarm_left_link2_collision" pos="0.0301 0 -0.1225" type="mesh" mesh="775eb093_link2_symp" />
            <body name="openarm_left_link3" pos="0.0301 0 0.06625">
              <inertial pos="-0.00210475 -0.000554909 0.0904747" quat="0.999951 -0.00493243 -0.00144148 0.00846755" mass="1.07386" diaginertia="0.00437205 0.00431934 0.000660613" />
              <joint name="openarm_left_joint3" pos="0 0 0" axis="0 0 1" range="-1.5708 1.5708" actuatorfrcrange="-27 27" class="arm_joint" />
              <geom name="openarm_left_link3_visual" pos="0 0 -0.18875" type="mesh" contype="0" conaffinity="0" group="1" density="0" mesh="95d3aa89_link3" />
              <geom name="openarm_left_link3_collision" pos="0 0 -0.18875" quat="1 0 0 0" type="mesh" mesh="dee04699_link3_symp" />
              <body name="openarm_left_link4" pos="0 0.0315 0.15375">
                <inertial pos="-0.00290068 -0.0303058 0.0633964" quat="0.994282 0.0996876 0.0329726 -0.0194356" mass="0.634853" diaginertia="0.000624355 0.000518596 0.000325049" />
                <joint name="openarm_left_joint4" pos="0 0 0" axis="0 1 0" range="0 2.44346" actuatorfrcrange="-27 27" class="arm_joint" />
                <geom name="openarm_left_link4_visual" pos="0 -0.0315 -0.3425" type="mesh" contype="0" conaffinity="0" group="1" density="0" mesh="c8eeff55_link4" />
                <geom name="openarm_left_link4_collision" pos="0 -0.0315 -0.3425" type="mesh" mesh="c98343f3_link4_symp" />
                <body name="orcahand_left_ForeArmStructure-Model_e18f2368" pos="0.01 -0.0315 0.153" quat="0.707107 0.707107 0 0">
                  <inertial pos="0 0 0" quat="0.52671 0.47178 -0.52671 0.47178" mass="7.42253" diaginertia="132.904 128.659 109.533" />
                  <geom type="mesh" contype="0" conaffinity="0" group="1" density="0" rgba="1 1 1 1" mesh="left_ForeArmStructure-Model" />
                  <geom type="mesh" rgba="1 1 1 1" mesh="left_ForeArmStructure-Model" />
                  <body name="orcahand_left_TopTower-Model_4a80d30e" pos="-0.01 0.0523 0" quat="0.5 -0.5 0.5 0.5">
                    <inertial pos="0 0 0" quat="0.497629 0.50236 -0.50236 0.497629" mass="0.185652" diaginertia="2.10033 1.64324 1.49927" />
                    <geom type="mesh" contype="0" conaffinity="0" group="1" density="0" rgba="1 1 1 1" mesh="left_TopTower-Model" />
                    <geom type="mesh" rgba="1 1 1 1" mesh="left_TopTower-Model" />
                    <body name="orcahand_left_L-Carpals_719fff8c" pos="0 0 0.04" quat="0.67438 -0.212631 0.212631 -0.67438">
                      <inertial pos="-0.005 -0.00187708 0.0495" quat="0.720781 -0.037936 -0.114965 0.682509" mass="0.854257" diaginertia="8.69897 5.73521 3.94922" />
                      <joint name="orcahand_left_L-Carpals_719fff8c_to_TopTower-Model_4a80d30e" pos="0 0 0" axis="-1 0 0" range="-1.13446 0.610865" actuatorfrcrange="-100 100" class="hand_joint" />
                      <geom pos="-0.005 -0.00187708 0.0495" quat="1 0 0 0" type="mesh" contype="0" conaffinity="0" group="1" density="0" rgba="1 1 1 1" mesh="left_L-Carpals" />
                      <geom pos="-0.005 -0.00187708 0.0495" quat="1 0 0 0" type="mesh" rgba="1 1 1 1" mesh="left_L-Carpals" />
                      <body name="orcahand_left_P-AP_f5e42b61" pos="-0.0356417 0.000689159 0.0620542" quat="0.546147 0.61386 0.340215 -0.457333">
                        <inertial pos="-0.01775 0 -0.001" quat="-5.37235e-05 0.678784 -8.25306e-07 0.734338" mass="0.00413586" diaginertia="0.00778563 0.00739789 0.00187075" />
                        <joint name="orcahand_left_P-AP_f5e42b61_to_L-Carpals_719fff8c" pos="0 0 0" axis="-0.13298 -0.348295 -0.927905" range="-0.523599 0.523599" actuatorfrcrange="-100 100" class="hand_joint" />
                        <geom pos="-0.01775 0 -0.001" quat="1 0 0 0" type="mesh" contype="0" conaffinity="0" group="1" density="0" rgba="1 1 1 1" mesh="left_P-AP" />
                        <geom pos="-0.01775 0 -0.001" quat="1 0 0 0" type="mesh" rgba="1 1 1 1" mesh="left_P-AP" />
                        <body name="orcahand_left_P-PP_1d411b9b" pos="-0.01775 0 -0.001" quat="0.707107 0 -0.707107 0">
                          <inertial pos="0 0 0" quat="0.757715 0.025739 0.0312903 0.651326" mass="0.00811738" diaginertia="0.0257942 0.0257696 0.00337209" />
                          <joint name="orcahand_left_P-PP_1d411b9b_to_P-AP_f5e42b61" pos="0 0 0" axis="0 -1 0" range="-0.436332 1.74533" actuatorfrcrange="-100 100" class="hand_joint" />
                          <geom type="mesh" contype="0" conaffinity="0" group="1" density="0" rgba="1 1 1 1" mesh="left_P-PP" />
                          <geom type="mesh" rgba="1 1 1 1" mesh="left_P-PP" />
                          <body name="orcahand_left_P-FingerTipAssembly_cd219176" pos="0.001 0 0.031" quat="1 0 0 0">
                            <inertial pos="0 0 0" quat="0.707239 -0.0192054 -0.0194271 0.706447" mass="0.0331906" diaginertia="0.121123 0.118798 0.00742277" />
                            <joint name="orcahand_left_P-FingerTipAssembly_cd219176_to_P-PP_1d411b9b" pos="0 0 0" axis="0 -1 0" range="-0.261799 1.8675" actuatorfrcrange="-100 100" class="hand_joint" />
                            <geom quat="1 0 0 0" type="mesh" contype="0" conaffinity="0" group="1" density="0" rgba="1 1 1 1" mesh="left_P-FingerTipAssembly" />
                            <geom quat="1 0 0 0" type="mesh" rgba="1 1 1 1" mesh="left_P-FingerTipAssembly" />
                          </body>
                        </body>
                      </body>
                      <body name="orcahand_left_M-AP_6ec59111" pos="-0.0153077 -0.00321836 0.0713048" quat="0.514389 0.554718 0.438507 -0.485185">
                        <inertial pos="-0.01925 0 -0.001" quat="-3.5747e-05 0.679132 -5.84224e-06 0.734016" mass="0.00492357" diaginertia="0.00995035 0.00946071 0.00266989" />
                        <joint name="orcahand_left_M-AP_6ec59111_to_L-Carpals_719fff8c" pos="0 0 0" axis="-0.0252081 -0.171809 -0.984808" range="-0.471239 0.471239" actuatorfrcrange="-100 100" class="hand_joint" />
                        <geom pos="-0.01925 0 -0.001" quat="1 0 0 0" type="mesh" contype="0" conaffinity="0" group="1" density="0" rgba="1 1 1 1" mesh="left_M-AP" />
                        <geom pos="-0.01925 0 -0.001" quat="1 0 0 0" type="mesh" rgba="1 1 1 1" mesh="left_M-AP" />
                        <body name="orcahand_left_M-PP_8660a1eb" pos="-0.019867 0 -0.001" quat="0.707107 0 -0.707107 0">
                          <inertial pos="0 0 0" quat="0.710924 0.0299631 0.0309106 0.70195" mass="0.0127336" diaginertia="0.065043 0.0644515 0.00647709" />
                          <joint name="orcahand_left_M-PP_8660a1eb_to_M-AP_6ec59111" pos="0 0 0" axis="0 -1 0" range="-0.436332 1.74533" actuatorfrcrange="-100 100" class="hand_joint" />
                          <geom type="mesh" contype="0" conaffinity="0" group="1" density="0" rgba="1 1 1 1" mesh="left_M-PP" />
                          <geom type="mesh" rgba="1 1 1 1" mesh="left_M-PP" />
                          <body name="orcahand_left_M-FingerTipAssembly_424a8e75" pos="0.002 0 0.04" quat="1 0 0 0">
                            <inertial pos="0 0 0" quat="0.708168 -0.0031601 -0.0032434 0.706029" mass="0.046737" diaginertia="0.240043 0.236778 0.0120566" />
                            <joint name="orcahand_left_M-FingerTipAssembly_424a8e75_to_M-PP_8660a1eb" pos="0 0 0" axis="0 -1 0" range="-0.261799 1.8675" actuatorfrcrange="-100 100" class="hand_joint" />
                            <geom type="mesh" contype="0" conaffinity="0" group="1" density="0" rgba="1 1 1 1" mesh="left_M-FingerTipAssembly" />
                            <geom type="mesh" rgba="1 1 1 1" mesh="left_M-FingerTipAssembly" />
                          </body>
                        </body>
                      </body>
                      <body name="orcahand_left_M-AP_e04a96f2" pos="0.00570633 -0.0040234 0.0785019" quat="0.499328 0.499328 0.500672 -0.500672">
                        <inertial pos="-0.01925 0 -0.001" quat="-3.5747e-05 0.679132 -5.84224e-06 0.734016" mass="0.00492357" diaginertia="0.00995035 0.00946071 0.00266989" />
                        <joint name="orcahand_left_M-AP_e04a96f2_to_L-Carpals_719fff8c" pos="0 0 0" axis="0 0 -1" range="-0.471239 0.471239" actuatorfrcrange="-100 100" class="hand_joint" />
                        <geom pos="-0.01925 0 -0.001" quat="1 0 0 0" type="mesh" contype="0" conaffinity="0" group="1" density="0" rgba="1 1 1 1" mesh="left_M-AP" />
                        <geom pos="-0.01925 0 -0.001" quat="1 0 0 0" type="mesh" rgba="1 1 1 1" mesh="left_M-AP" />
                        <body name="orcahand_left_M-PP_08efa608" pos="-0.019867 0 -0.001" quat="0.707107 0 -0.707107 0">
                          <inertial pos="0 0 0" quat="0.710924 0.0299631 0.0309106 0.70195" mass="0.0127336" diaginertia="0.065043 0.0644515 0.00647709" />
                          <joint name="orcahand_left_M-PP_08efa608_to_M-AP_e04a96f2" pos="0 0 0" axis="0 -1 0" range="-0.436332 1.74533" actuatorfrcrange="-100 100" class="hand_joint" />
                          <geom type="mesh" contype="0" conaffinity="0" group="1" density="0" rgba="1 1 1 1" mesh="left_M-PP" />
                          <geom type="mesh" rgba="1 1 1 1" mesh="left_M-PP" />
                          <body name="orcahand_left_M-FingerTipAssembly_34afb748" pos="0.002 0 0.04" quat="1 0 0 0">
                            <inertial pos="0 0 0" quat="0.708168 -0.0031601 -0.0032434 0.706029" mass="0.046737" diaginertia="0.240043 0.236778 0.0120566" />
                            <joint name="orcahand_left_M-FingerTipAssembly_34afb748_to_M-PP_08efa608" pos="0 0 0" axis="0 -1 0" range="-0.261799 1.8675" actuatorfrcrange="-100 100" class="hand_joint" />
                            <geom type="mesh" contype="0" conaffinity="0" group="1" density="0" rgba="1 1 1 1" mesh="left_M-FingerTipAssembly" />
                            <geom type="mesh" rgba="1 1 1 1" mesh="left_M-FingerTipAssembly" />
                          </body>
                        </body>
                      </body>
                      <body name="orcahand_left_I-AP-L_57ce92f7" pos="0.027241 -0.00220697 0.0694068" quat="0.471638 0.43178 0.566686 -0.519606">
                        <inertial pos="-0.01875 0 -0.001" quat="0.000634884 0.679523 -0.00181331 0.733651" mass="0.00458154" diaginertia="0.00911894 0.00863269 0.00235592" />
                        <joint name="orcahand_left_I-AP-L_57ce92f7_to_L-Carpals_719fff8c" pos="0 0 0" axis="-0.0312851 0.168144 -0.985266" range="-0.436332 0.523599" actuatorfrcrange="-100 100" class="hand_joint" />
                        <geom pos="-0.01875 0 -0.001" quat="1 0 0 0" type="mesh" contype="0" conaffinity="0" group="1" density="0" rgba="1 1 1 1" mesh="left_I-AP-L" />
                        <geom pos="-0.01875 0 -0.001" quat="1 0 0 0" type="mesh" rgba="1 1 1 1" mesh="left_I-AP-L" />
                        <body name="orcahand_left_I-PP_3df4f91d" pos="-0.019151 0 -0.001" quat="0.707107 0 -0.707107 0">
                          <inertial pos="0 0 0" quat="0.71414 0.0281053 0.0294667 0.698817" mass="0.0113732" diaginertia="0.050424 0.0501383 0.00557676" />
                          <joint name="orcahand_left_I-PP_3df4f91d_to_I-AP-L_57ce92f7" pos="0 0 0" axis="0 -1 0" range="-0.436332 1.74533" actuatorfrcrange="-100 100" class="hand_joint" />
                          <geom type="mesh" contype="0" conaffinity="0" group="1" density="0" rgba="1 1 1 1" mesh="left_I-PP" />
                          <geom type="mesh" rgba="1 1 1 1" mesh="left_I-PP" />
                          <body name="orcahand_left_I-FingerTipAssembly_ed91b18a" pos="0.0015 0 0.037" quat="1 0 0 0">
                            <inertial pos="0 0 0" quat="0.708119 -0.00312739 -0.00320556 0.706079" mass="0.0467518" diaginertia="0.240127 0.236855 0.0120639" />
                            <joint name="orcahand_left_I-FingerTipAssembly_ed91b18a_to_I-PP_3df4f91d" pos="0 0 0" axis="0 -1 0" range="-0.261799 1.8675" actuatorfrcrange="-100 100" class="hand_joint" />
                            <geom type="mesh" contype="0" conaffinity="0" group="1" density="0" rgba="1 1 1 1" mesh="left_I-FingerTipAssembly" />
                            <geom type="mesh" rgba="1 1 1 1" mesh="left_I-FingerTipAssembly" />
                          </body>
                        </body>
                      </body>
                      <body name="orcahand_left_T-TP-L_92b8100b" pos="0.0283987 0.0109972 0.0305895" quat="0.656374 -0.0725704 0.359491 -0.659297">
                        <inertial pos="0 0 -0.00385" quat="0.988591 -0.0305764 0.00464261 0.147419" mass="0.00797957" diaginertia="0.0142622 0.0118005 0.00673248" />
                        <joint name="orcahand_left_T-TP-L_92b8100b_to_L-Carpals_719fff8c" pos="0 0 0" axis="0 0 1" range="-0.785398 0.575959" actuatorfrcrange="-100 100" class="hand_joint" />
                        <geom pos="0 0 -0.00385" type="mesh" contype="0" conaffinity="0" group="1" density="0" rgba="1 1 1 1" mesh="left_T-TP-L" />
                        <geom pos="0 0 -0.00385" type="mesh" rgba="1 1 1 1" mesh="left_T-TP-L" />
                        <body name="orcahand_left_L-T-AP_58680c44" pos="-0.008 0 -0.00385" quat="0.819152 0.573576 0 0">
                          <inertial pos="-0.028 0 0" quat="-0.00257672 0.708684 -0.0023663 0.705518" mass="0.00700533" diaginertia="0.0263214 0.0256059 0.00373538" />
                          <joint name="orcahand_left_L-T-AP_58680c44_to_T-TP-L_92b8100b" pos="0 0 0" axis="0 0.34202 -0.939693" range="-0.314159 0.959931" actuatorfrcrange="-100 100" class="hand_joint" />
                          <geom pos="-0.028 0 0" quat="1 0 0 0" type="mesh" contype="0" conaffinity="0" group="1" density="0" rgba="1 1 1 1" mesh="left_L-T-AP" />
                          <geom pos="-0.028 0 0" quat="1 0 0 0" type="mesh" rgba="1 1 1 1" mesh="left_L-T-AP" />
                          <body name="orcahand_left_T-PP_ef067304" pos="-0.028 0 0" quat="0 -0.707107 0 0.707107">
                            <inertial pos="0 0 0" quat="0.999128 -0.000624401 0.0411148 0.00722351" mass="0.0104908" diaginertia="0.0343537 0.0339831 0.00539594" />
                            <joint name="orcahand_left_T-PP_ef067304_to_L-T-AP_58680c44" pos="0 0 0" axis="0 -1 0" range="-0.436332 1.74533" actuatorfrcrange="-100 100" class="hand_joint" />
                            <geom type="mesh" contype="0" conaffinity="0" group="1" density="0" rgba="1 1 1 1" mesh="left_T-PP" />
                            <geom type="mesh" rgba="1 1 1 1" mesh="left_T-PP" />
                            <body name="orcahand_left_T-DP_307db3cc" pos="0.001 0 0.032" quat="1 0 0 0">
                              <inertial pos="0 0 0" quat="0.999812 0.00067269 0.0184706 0.00594227" mass="0.00815769" diaginertia="0.0215832 0.0210638 0.00324334" />
                              <joint name="orcahand_left_T-DP_307db3cc_to_T-PP_ef067304" pos="0 0 0" axis="0 -1 0" range="-0.261799 1.8675" actuatorfrcrange="-100 100" class="hand_joint" />
                              <geom type="mesh" contype="0" conaffinity="0" group="1" density="0" rgba="1 1 1 1" mesh="left_T-DP" />
                              <geom type="mesh" rgba="1 1 1 1" mesh="left_T-DP" />
                            </body>
                          </body>
                        </body>
                      </body>
                    </body>
                  </body>
                </body>
              </body>
            </body>
          </body>
        </body>
      </body>
      <body name="openarm_right_link0" pos="0 -0.031 0.698" quat="0.707105 0.707108 0 0">
        <inertial pos="-0.000948336 0.000158021 0.0307686" quat="0.479051 0.472241 -0.533622 0.512587" mass="1.14323" diaginertia="0.00147324 0.00112498 0.000961783" />
        <geom name="openarm_right_link0_visual" type="mesh" contype="0" conaffinity="0" group="1" density="0" mesh="9ba3e77f_link01" />
        <geom name="openarm_right_link0_collision" type="mesh" mesh="5da9d14d_link0_symp1" />
        <body name="openarm_right_link1" pos="0 0 0.0625">
          <inertial pos="0.00114677 3.31999e-05 0.0539528" quat="0.999653 0.00178277 0.0262159 -0.0018256" mass="1.14167" diaginertia="0.00156853 0.001273 0.00101447" />
          <joint name="openarm_right_joint1" pos="0 0 0" axis="0 0 1" range="-1.39626 3.49066" actuatorfrcrange="-40 40" class="arm_joint" />
          <geom name="openarm_right_link1_visual" pos="0 0 -0.0625" type="mesh" contype="0" conaffinity="0" group="1" density="0" mesh="3ebfcf76_link11" />
          <geom name="openarm_right_link1_collision" pos="0 0 -0.0625" type="mesh" mesh="77e5ad00_link1_symp1" />
          <body name="openarm_right_link2" pos="-0.0301 0 0.06" quat="0.707107 0.707107 0 0">
            <inertial pos="0.00839629 -2.01451e-08 0.0325665" quat="0.966167 0.00423301 0.257864 0.00305037" mass="0.277509" diaginertia="0.000421651 0.000376006 0.000169343" />
            <joint name="openarm_right_joint2" pos="0 0 0" axis="-1 0 0" range="-0.174533 3.31613" actuatorfrcrange="-40 40" class="arm_joint" />
            <geom name="openarm_right_link2_visual" pos="0.0301 0 -0.1225" type="mesh" contype="0" conaffinity="0" group="1" density="0" mesh="9c17496a_link21" />
            <geom name="openarm_right_link2_collision" pos="0.0301 0 -0.1225" type="mesh" mesh="775eb093_link2_symp1" />
            <body name="openarm_right_link3" pos="0.0301 0 0.06625">
              <inertial pos="-0.00210475 0.000554909 0.0904747" quat="0.999951 -0.00493243 -0.00144148 0.00846755" mass="1.07386" diaginertia="0.00437205 0.00431934 0.000660613" />
              <joint name="openarm_right_joint3" pos="0 0 0" axis="0 0 1" range="-1.5708 1.5708" actuatorfrcrange="-27 27" class="arm_joint" />
              <geom name="openarm_right_link3_visual" pos="0 0 -0.18875" type="mesh" contype="0" conaffinity="0" group="1" density="0" mesh="95d3aa89_link31" />
              <geom name="openarm_right_link3_collision" pos="0 0 -0.18875" quat="1 0 0 0" type="mesh" mesh="dee04699_link3_symp1" />
              <body name="openarm_right_link4" pos="0 0.0315 0.15375">
                <inertial pos="-0.00290068 -0.0303058 0.0633964" quat="0.994282 0.0996876 0.0329726 -0.0194356" mass="0.634853" diaginertia="0.000624355 0.000518596 0.000325049" />
                <joint name="openarm_right_joint4" pos="0 0 0" axis="0 1 0" range="0 2.44346" actuatorfrcrange="-27 27" class="arm_joint" />
                <geom name="openarm_right_link4_visual" pos="0 -0.0315 -0.3425" type="mesh" contype="0" conaffinity="0" group="1" density="0" mesh="c8eeff55_link4" />
                <geom name="openarm_right_link4_collision" pos="0 -0.0315 -0.3425" type="mesh" mesh="c98343f3_link4_symp" />
                <body name="orcahand_right_ForeArmStructure-Model_e18f2368" pos="-0.01 -0.0315 0.153" quat="0 0 0.707107 0.707107">
                  <inertial pos="0 0 0" quat="0.52671 0.47178 -0.52671 0.47178" mass="7.42253" diaginertia="132.904 128.659 109.533" />
                  <geom type="mesh" contype="0" conaffinity="0" group="1" density="0" rgba="1 1 1 1" mesh="right_ForeArmStructure-Model" />
                  <geom type="mesh" rgba="1 1 1 1" mesh="right_ForeArmStructure-Model" />
                  <body name="orcahand_right_TopTower-Model_4a80d30e" pos="-0.01 0.0523 0" quat="0.5 -0.5 0.5 0.5">
                    <inertial pos="0 0 0" quat="0.497629 0.50236 -0.50236 0.497629" mass="0.185652" diaginertia="2.10033 1.64324 1.49927" />
                    <geom type="mesh" contype="0" conaffinity="0" group="1" density="0" rgba="1 1 1 1" mesh="right_TopTower-Model" />
                    <geom type="mesh" rgba="1 1 1 1" mesh="right_TopTower-Model" />
                    <body name="orcahand_right_R-Carpals_8d1f1041" pos="0 0 0.04" quat="0.67438 -0.212631 0.212631 -0.67438">
                      <inertial pos="-0.005 -0.00187708 0.0495" quat="0.676949 -0.122061 -0.169645 0.705734" mass="0.135388" diaginertia="1.71432 1.29706 0.574665" />
                      <joint name="orcahand_right_R-Carpals_8d1f1041_to_TopTower-Model_4a80d30e" pos="0 0 0" axis="-1 0 0" range="-1.13446 0.610865" actuatorfrcrange="-100 100" class="hand_joint" />
                      <geom pos="-0.005 -0.00187708 0.0495" quat="1 0 0 0" type="mesh" contype="0" conaffinity="0" group="1" density="0" rgba="1 1 1 1" mesh="right_R-Carpals" />
                      <geom pos="-0.005 -0.00187708 0.0495" quat="1 0 0 0" type="mesh" rgba="1 1 1 1" mesh="right_R-Carpals" />
                      <body name="orcahand_right_P-AP_f5e42b61" pos="0.0356417 0.000689159 0.0620542" quat="0.457318 0.340199 0.613869 -0.546159">
                        <inertial pos="-0.01775 0 -0.001" quat="-5.37235e-05 0.678784 -8.25306e-07 0.734338" mass="0.00413586" diaginertia="0.00778563 0.00739789 0.00187075" />
                        <joint name="orcahand_right_P-AP_f5e42b61_to_R-Carpals_8d1f1041" pos="0 0 0" axis="0 0 1" range="-0.523599 0.523599" actuatorfrcrange="-100 100" class="hand_joint" />
                        <geom pos="-0.01775 0 -0.001" quat="1 0 0 0" type="mesh" contype="0" conaffinity="0" group="1" density="0" rgba="1 1 1 1" mesh="right_P-AP" />
                        <geom pos="-0.01775 0 -0.001" quat="1 0 0 0" type="mesh" rgba="1 1 1 1" mesh="right_P-AP" />
                        <body name="orcahand_right_P-PP_1d411b9b" pos="-0.01775 0 -0.001" quat="0.707107 0 -0.707107 0">
                          <inertial pos="0 0 0" quat="0.757715 0.025739 0.0312903 0.651326" mass="0.00811738" diaginertia="0.0257942 0.0257696 0.00337209" />
                          <joint name="orcahand_right_P-PP_1d411b9b_to_P-AP_f5e42b61" pos="0 0 0" axis="0 -1 0" range="-0.436332 1.74533" actuatorfrcrange="-100 100" class="hand_joint" />
                          <geom type="mesh" contype="0" conaffinity="0" group="1" density="0" rgba="1 1 1 1" mesh="right_P-PP" />
                          <geom type="mesh" rgba="1 1 1 1" mesh="right_P-PP" />
                          <body name="orcahand_right_P-FingerTipAssembly_cd219176" pos="0.001 0 0.031" quat="1 0 0 0">
                            <inertial pos="0 0 0" quat="0.707239 -0.0192054 -0.0194271 0.706447" mass="0.0331906" diaginertia="0.121123 0.118798 0.00742277" />
                            <joint name="orcahand_right_P-FingerTipAssembly_cd219176_to_P-PP_1d411b9b" pos="0 0 0" axis="0 -1 0" range="-0.261799 1.8675" actuatorfrcrange="-100 100" class="hand_joint" />
                            <geom type="mesh" contype="0" conaffinity="0" group="1" density="0" rgba="1 1 1 1" mesh="right_P-FingerTipAssembly" />
                            <geom type="mesh" rgba="1 1 1 1" mesh="right_P-FingerTipAssembly" />
                          </body>
                        </body>
                      </body>
                      <body name="orcahand_right_M-AP_6ec59111" pos="0.0153077 -0.00321836 0.0713048" quat="0.485171 0.438492 0.554729 -0.514401">
                        <inertial pos="-0.01925 0 -0.001" quat="-3.5747e-05 0.679132 -5.84224e-06 0.734016" mass="0.00492357" diaginertia="0.00995035 0.00946071 0.00266989" />
                        <joint name="orcahand_right_M-AP_6ec59111_to_R-Carpals_8d1f1041" pos="0 0 0" axis="0 0 1" range="-0.471239 0.471239" actuatorfrcrange="-100 100" class="hand_joint" />
                        <geom pos="-0.01925 0 -0.001" quat="1 0 0 0" type="mesh" contype="0" conaffinity="0" group="1" density="0" rgba="1 1 1 1" mesh="right_M-AP" />
                        <geom pos="-0.01925 0 -0.001" quat="1 0 0 0" type="mesh" rgba="1 1 1 1" mesh="right_M-AP" />
                        <body name="orcahand_right_M-PP_8660a1eb" pos="-0.019867 0 -0.001" quat="0.707107 0 -0.707107 0">
                          <inertial pos="0 0 0" quat="0.710924 0.0299631 0.0309106 0.70195" mass="0.0127336" diaginertia="0.065043 0.0644515 0.00647709" />
                          <joint name="orcahand_right_M-PP_8660a1eb_to_M-AP_6ec59111" pos="0 0 0" axis="0 -1 0" range="-0.436332 1.74533" actuatorfrcrange="-100 100" class="hand_joint" />
                          <geom type="mesh" contype="0" conaffinity="0" group="1" density="0" rgba="1 1 1 1" mesh="right_M-PP" />
                          <geom type="mesh" rgba="1 1 1 1" mesh="right_M-PP" />
                          <body name="orcahand_right_M-FingerTipAssembly_424a8e75" pos="0.002 0 0.04" quat="1 0 0 0">
                            <inertial pos="0 0 0" quat="0.708168 -0.0031601 -0.0032434 0.706029" mass="0.046737" diaginertia="0.240043 0.236778 0.0120566" />
                            <joint name="orcahand_right_M-FingerTipAssembly_424a8e75_to_M-PP_8660a1eb" pos="0 0 0" axis="0 -1 0" range="-0.261799 1.8675" actuatorfrcrange="-100 100" class="hand_joint" />
                            <geom type="mesh" contype="0" conaffinity="0" group="1" density="0" rgba="1 1 1 1" mesh="right_M-FingerTipAssembly" />
                            <geom type="mesh" rgba="1 1 1 1" mesh="right_M-FingerTipAssembly" />
                          </body>
                        </body>
                      </body>
                      <body name="orcahand_right_M-AP_e04a96f2" pos="-0.00570633 -0.0040234 0.0785019" quat="0.500654 0.500654 0.499345 -0.499345">
                        <inertial pos="-0.01925 0 -0.001" quat="-3.5747e-05 0.679132 -5.84224e-06 0.734016" mass="0.00492357" diaginertia="0.00995035 0.00946071 0.00266989" />
                        <joint name="orcahand_right_M-AP_e04a96f2_to_R-Carpals_8d1f1041" pos="0 0 0" axis="0 0 1" range="-0.471239 0.471239" actuatorfrcrange="-100 100" class="hand_joint" />
                        <geom pos="-0.01925 0 -0.001" quat="1 0 0 0" type="mesh" contype="0" conaffinity="0" group="1" density="0" rgba="1 1 1 1" mesh="right_M-AP" />
                        <geom pos="-0.01925 0 -0.001" quat="1 0 0 0" type="mesh" rgba="1 1 1 1" mesh="right_M-AP" />
                        <body name="orcahand_right_M-PP_08efa608" pos="-0.019867 0 -0.001" quat="0.707107 0 -0.707107 0">
                          <inertial pos="0 0 0" quat="0.710924 0.0299631 0.0309106 0.70195" mass="0.0127336" diaginertia="0.065043 0.0644515 0.00647709" />
                          <joint name="orcahand_right_M-PP_08efa608_to_M-AP_e04a96f2" pos="0 0 0" axis="0 -1 0" range="-0.436332 1.74533" actuatorfrcrange="-100 100" class="hand_joint" />
                          <geom type="mesh" contype="0" conaffinity="0" group="1" density="0" rgba="1 1 1 1" mesh="right_M-PP" />
                          <geom type="mesh" rgba="1 1 1 1" mesh="right_M-PP" />
                          <body name="orcahand_right_M-FingerTipAssembly_34afb748" pos="0.002 0 0.04" quat="1 0 0 0">
                            <inertial pos="0 0 0" quat="0.708168 -0.0031601 -0.0032434 0.706029" mass="0.046737" diaginertia="0.240043 0.236778 0.0120566" />
                            <joint name="orcahand_right_M-FingerTipAssembly_34afb748_to_M-PP_08efa608" pos="0 0 0" axis="0 -1 0" range="-0.261799 1.8675" actuatorfrcrange="-100 100" class="hand_joint" />
                            <geom type="mesh" contype="0" conaffinity="0" group="1" density="0" rgba="1 1 1 1" mesh="right_M-FingerTipAssembly" />
                            <geom type="mesh" rgba="1 1 1 1" mesh="right_M-FingerTipAssembly" />
                          </body>
                        </body>
                      </body>
                      <body name="orcahand_right_I-AP-R_d95d02d1" pos="-0.027241 -0.00220697 0.0694068" quat="0.519647 0.566724 0.43173 -0.471593">
                        <inertial pos="-0.01875 0 -0.001" quat="-0.00068369 0.679605 0.00174529 0.733576" mass="0.00459029" diaginertia="0.00916177 0.00867545 0.00235798" />
                        <joint name="orcahand_right_I-AP-R_d95d02d1_to_R-Carpals_8d1f1041" pos="0 0 0" axis="0 0 1" range="-0.436332 0.523599" actuatorfrcrange="-100 100" class="hand_joint" />
                        <geom pos="-0.01875 0 -0.001" quat="1 0 0 0" type="mesh" contype="0" conaffinity="0" group="1" density="0" rgba="1 1 1 1" mesh="right_I-AP-R" />
                        <geom pos="-0.01875 0 -0.001" quat="1 0 0 0" type="mesh" rgba="1 1 1 1" mesh="right_I-AP-R" />
                        <body name="orcahand_right_I-PP_bacbd481" pos="-0.019151 0 -0.001" quat="0.707107 0 -0.707107 0">
                          <inertial pos="0 0 0" quat="0.71414 0.0281053 0.0294667 0.698817" mass="0.0113732" diaginertia="0.050424 0.0501383 0.00557676" />
                          <joint name="orcahand_right_I-PP_bacbd481_to_I-AP-R_d95d02d1" pos="0 0 0" axis="0 -1 0" range="-0.436332 1.74533" actuatorfrcrange="-100 100" class="hand_joint" />
                          <geom type="mesh" contype="0" conaffinity="0" group="1" density="0" rgba="1 1 1 1" mesh="right_I-PP" />
                          <geom type="mesh" rgba="1 1 1 1" mesh="right_I-PP" />
                          <body name="orcahand_right_I-FingerTipAssembly_ec49c16c" pos="0.0015 0 0.037" quat="1 0 0 0">
                            <inertial pos="0 0 0" quat="0.708119 -0.00312739 -0.00320556 0.706079" mass="0.0467518" diaginertia="0.240127 0.236855 0.0120639" />
                            <joint name="orcahand_right_I-FingerTipAssembly_ec49c16c_to_I-PP_bacbd481" pos="0 0 0" axis="0 -1 0" range="-0.261799 1.8675" actuatorfrcrange="-100 100" class="hand_joint" />
                            <geom type="mesh" contype="0" conaffinity="0" group="1" density="0" rgba="1 1 1 1" mesh="right_I-FingerTipAssembly" />
                            <geom type="mesh" rgba="1 1 1 1" mesh="right_I-FingerTipAssembly" />
                          </body>
                        </body>
                      </body>
                      <body name="orcahand_right_T-TP-R_1c2b802d" pos="-0.0283987 0.0109972 0.0305895" quat="0.659119 0.359511 -0.0724731 -0.656553">
                        <inertial pos="0 0 -0.00385" quat="0.98859 0.0305699 0.00467681 -0.147425" mass="0.00797873" diaginertia="0.0142608 0.011799 0.00673214" />
                        <joint name="orcahand_right_T-TP-R_1c2b802d_to_R-Carpals_8d1f1041" pos="0 0 0" axis="0 0 -1" range="-0.785398 0.575959" actuatorfrcrange="-100 100" class="hand_joint" />
                        <geom pos="0 0 -0.00385" type="mesh" contype="0" conaffinity="0" group="1" density="0" rgba="1 1 1 1" mesh="right_T-TP-R" />
                        <geom pos="0 0 -0.00385" type="mesh" rgba="1 1 1 1" mesh="right_T-TP-R" />
                        <body name="orcahand_right_R-T-AP_a9723101" pos="-0.008 0 -0.00385" quat="0.819152 -0.573576 0 0">
                          <inertial pos="-0.028 0 0" quat="0.00297698 0.708595 0.00227712 0.705606" mass="0.00700414" diaginertia="0.0263154 0.0256004 0.00373501" />
                          <joint name="orcahand_right_R-T-AP_a9723101_to_T-TP-R_1c2b802d" pos="0 0 0" axis="0 0.34202 0.939693" range="-0.314159 0.959931" actuatorfrcrange="-100 100" class="hand_joint" />
                          <geom pos="-0.028 0 0" quat="1 0 0 0" type="mesh" contype="0" conaffinity="0" group="1" density="0" rgba="1 1 1 1" mesh="right_R-T-AP" />
                          <geom pos="-0.028 0 0" quat="1 0 0 0" type="mesh" rgba="1 1 1 1" mesh="right_R-T-AP" />
                          <body name="orcahand_right_T-PP_68395e98" pos="-0.028 0 0" quat="0 -0.707107 0 0.707107">
                            <inertial pos="0 0 0" quat="0.999128 -0.000624401 0.0411148 0.00722351" mass="0.0104908" diaginertia="0.0343537 0.0339831 0.00539594" />
                            <joint name="orcahand_right_T-PP_68395e98_to_R-T-AP_a9723101" pos="0 0 0" axis="0 -1 0" range="-0.436332 1.74533" actuatorfrcrange="-100 100" class="hand_joint" />
                            <geom type="mesh" contype="0" conaffinity="0" group="1" density="0" rgba="1 1 1 1" mesh="right_T-PP" />
                            <geom type="mesh" rgba="1 1 1 1" mesh="right_T-PP" />
                            <body name="orcahand_right_T-DP_b7429e50" pos="0.001 0 0.032" quat="1 0 0 0">
                              <inertial pos="0 0 0" quat="0.999812 0.00067269 0.0184706 0.00594227" mass="0.00815769" diaginertia="0.0215832 0.0210638 0.00324334" />
                              <joint name="orcahand_right_T-DP_b7429e50_to_T-PP_68395e98" pos="0 0 0" axis="0 -1 0" range="-0.261799 1.8675" actuatorfrcrange="-100 100" class="hand_joint" />
                              <geom pos="0 0 0" type="mesh" contype="0" conaffinity="0" group="1" density="0" rgba="1 1 1 1" mesh="right_T-DP" />
                              <geom pos="0 0 0" type="mesh" rgba="1 1 1 1" mesh="right_T-DP" />
                            </body>
                          </body>
                        </body>
                      </body>
                    </body>
                  </body>
                </body>
              </body>
            </body>
          </body>
        </body>
      </body>
    </body>
  </worldbody>
  <actuator>
    <position class="arm_joint" name="act_openarm_left_joint1" joint="openarm_left_joint1" />
    <position class="arm_joint" name="act_openarm_left_joint2" joint="openarm_left_joint2" />
    <position class="arm_joint" name="act_openarm_left_joint3" joint="openarm_left_joint3" />
    <position class="arm_joint" name="act_openarm_left_joint4" joint="openarm_left_joint4" />
    <position class="hand_joint" name="act_orcahand_left_L-Carpals_719fff8c_to_TopTower-Model_4a80d30e" joint="orcahand_left_L-Carpals_719fff8c_to_TopTower-Model_4a80d30e" />
    <position class="hand_joint" name="act_orcahand_left_P-AP_f5e42b61_to_L-Carpals_719fff8c" joint="orcahand_left_P-AP_f5e42b61_to_L-Carpals_719fff8c" />
    <position class="hand_joint" name="act_orcahand_left_P-PP_1d411b9b_to_P-AP_f5e42b61" joint="orcahand_left_P-PP_1d411b9b_to_P-AP_f5e42b61" />
    <position class="hand_joint" name="act_orcahand_left_P-FingerTipAssembly_cd219176_to_P-PP_1d411b9b" joint="orcahand_left_P-FingerTipAssembly_cd219176_to_P-PP_1d411b9b" />
    <position class="hand_joint" name="act_orcahand_left_M-AP_6ec59111_to_L-Carpals_719fff8c" joint="orcahand_left_M-AP_6ec59111_to_L-Carpals_719fff8c" />
    <position class="hand_joint" name="act_orcahand_left_M-PP_8660a1eb_to_M-AP_6ec59111" joint="orcahand_left_M-PP_8660a1eb_to_M-AP_6ec59111" />
    <position class="hand_joint" name="act_orcahand_left_M-FingerTipAssembly_424a8e75_to_M-PP_8660a1eb" joint="orcahand_left_M-FingerTipAssembly_424a8e75_to_M-PP_8660a1eb" />
    <position class="hand_joint" name="act_orcahand_left_M-AP_e04a96f2_to_L-Carpals_719fff8c" joint="orcahand_left_M-AP_e04a96f2_to_L-Carpals_719fff8c" />
    <position class="hand_joint" name="act_orcahand_left_M-PP_08efa608_to_M-AP_e04a96f2" joint="orcahand_left_M-PP_08efa608_to_M-AP_e04a96f2" />
    <position class="hand_joint" name="act_orcahand_left_M-FingerTipAssembly_34afb748_to_M-PP_08efa608" joint="orcahand_left_M-FingerTipAssembly_34afb748_to_M-PP_08efa608" />
    <position class="hand_joint" name="act_orcahand_left_I-AP-L_57ce92f7_to_L-Carpals_719fff8c" joint="orcahand_left_I-AP-L_57ce92f7_to_L-Carpals_719fff8c" />
    <position class="hand_joint" name="act_orcahand_left_I-PP_3df4f91d_to_I-AP-L_57ce92f7" joint="orcahand_left_I-PP_3df4f91d_to_I-AP-L_57ce92f7" />
    <position class="hand_joint" name="act_orcahand_left_I-FingerTipAssembly_ed91b18a_to_I-PP_3df4f91d" joint="orcahand_left_I-FingerTipAssembly_ed91b18a_to_I-PP_3df4f91d" />
    <position class="hand_joint" name="act_orcahand_left_T-TP-L_92b8100b_to_L-Carpals_719fff8c" joint="orcahand_left_T-TP-L_92b8100b_to_L-Carpals_719fff8c" />
    <position class="hand_joint" name="act_orcahand_left_L-T-AP_58680c44_to_T-TP-L_92b8100b" joint="orcahand_left_L-T-AP_58680c44_to_T-TP-L_92b8100b" />
    <position class="hand_joint" name="act_orcahand_left_T-PP_ef067304_to_L-T-AP_58680c44" joint="orcahand_left_T-PP_ef067304_to_L-T-AP_58680c44" />
    <position class="hand_joint" name="act_orcahand_left_T-DP_307db3cc_to_T-PP_ef067304" joint="orcahand_left_T-DP_307db3cc_to_T-PP_ef067304" />
    <position class="arm_joint" name="act_openarm_right_joint1" joint="openarm_right_joint1" />
    <position class="arm_joint" name="act_openarm_right_joint2" joint="openarm_right_joint2" />
    <position class="arm_joint" name="act_openarm_right_joint3" joint="openarm_right_joint3" />
    <position class="arm_joint" name="act_openarm_right_joint4" joint="openarm_right_joint4" />
    <position class="hand_joint" name="act_orcahand_right_R-Carpals_8d1f1041_to_TopTower-Model_4a80d30e" joint="orcahand_right_R-Carpals_8d1f1041_to_TopTower-Model_4a80d30e" />
    <position class="hand_joint" name="act_orcahand_right_P-AP_f5e42b61_to_R-Carpals_8d1f1041" joint="orcahand_right_P-AP_f5e42b61_to_R-Carpals_8d1f1041" />
    <position class="hand_joint" name="act_orcahand_right_P-PP_1d411b9b_to_P-AP_f5e42b61" joint="orcahand_right_P-PP_1d411b9b_to_P-AP_f5e42b61" />
    <position class="hand_joint" name="act_orcahand_right_P-FingerTipAssembly_cd219176_to_P-PP_1d411b9b" joint="orcahand_right_P-FingerTipAssembly_cd219176_to_P-PP_1d411b9b" />
    <position class="hand_joint" name="act_orcahand_right_M-AP_6ec59111_to_R-Carpals_8d1f1041" joint="orcahand_right_M-AP_6ec59111_to_R-Carpals_8d1f1041" />
    <position class="hand_joint" name="act_orcahand_right_M-PP_8660a1eb_to_M-AP_6ec59111" joint="orcahand_right_M-PP_8660a1eb_to_M-AP_6ec59111" />
    <position class="hand_joint" name="act_orcahand_right_M-FingerTipAssembly_424a8e75_to_M-PP_8660a1eb" joint="orcahand_right_M-FingerTipAssembly_424a8e75_to_M-PP_8660a1eb" />
    <position class="hand_joint" name="act_orcahand_right_M-AP_e04a96f2_to_R-Carpals_8d1f1041" joint="orcahand_right_M-AP_e04a96f2_to_R-Carpals_8d1f1041" />
    <position class="hand_joint" name="act_orcahand_right_M-PP_08efa608_to_M-AP_e04a96f2" joint="orcahand_right_M-PP_08efa608_to_M-AP_e04a96f2" />
    <position class="hand_joint" name="act_orcahand_right_M-FingerTipAssembly_34afb748_to_M-PP_08efa608" joint="orcahand_right_M-FingerTipAssembly_34afb748_to_M-PP_08efa608" />
    <position class="hand_joint" name="act_orcahand_right_I-AP-R_d95d02d1_to_R-Carpals_8d1f1041" joint="orcahand_right_I-AP-R_d95d02d1_to_R-Carpals_8d1f1041" />
    <position class="hand_joint" name="act_orcahand_right_I-PP_bacbd481_to_I-AP-R_d95d02d1" joint="orcahand_right_I-PP_bacbd481_to_I-AP-R_d95d02d1" />
    <position class="hand_joint" name="act_orcahand_right_I-FingerTipAssembly_ec49c16c_to_I-PP_bacbd481" joint="orcahand_right_I-FingerTipAssembly_ec49c16c_to_I-PP_bacbd481" />
    <position class="hand_joint" name="act_orcahand_right_T-TP-R_1c2b802d_to_R-Carpals_8d1f1041" joint="orcahand_right_T-TP-R_1c2b802d_to_R-Carpals_8d1f1041" />
    <position class="hand_joint" name="act_orcahand_right_R-T-AP_a9723101_to_T-TP-R_1c2b802d" joint="orcahand_right_R-T-AP_a9723101_to_T-TP-R_1c2b802d" />
    <position class="hand_joint" name="act_orcahand_right_T-PP_68395e98_to_R-T-AP_a9723101" joint="orcahand_right_T-PP_68395e98_to_R-T-AP_a9723101" />
    <position class="hand_joint" name="act_orcahand_right_T-DP_b7429e50_to_T-PP_68395e98" joint="orcahand_right_T-DP_b7429e50_to_T-PP_68395e98" />
  </actuator>
</mujoco>